<?xml version="1.0" ?>
<!-- =================================================================================== -->
<!-- |    This document was autogenerated by xacro from /home/anthony/mine/ROS_noetic/robot_arm/src/ar3_model/urdf/ar3_copy.xacro | -->
<!-- |    EDITING THIS FILE BY HAND IS NOT RECOMMENDED                                 | -->
<!-- =================================================================================== -->
<!-- =================================================================================== -->
<!-- |    This document was autogenerated by xacro from ar3.urdf                       | -->
<!-- |    EDITING THIS FILE BY HAND IS NOT RECOMMENDED                                 | -->
<!-- =================================================================================== -->
<robot name="ar3">
    <link name="world" />
    <link name="base_footprint">
        <visual>
            <geometry>
                <sphere radius="0.001" />
            </geometry>
        </visual>
        <collision>
            <geometry>
                <sphere radius="0.001" />
            </geometry>
        </collision>
        <inertial>
            <mass value="0.01" />
            <origin xyz="0 0 0" rpy="0 0 0" />
            <inertia ixx="0.0001" iyy="0" izz="0.0001" ixy="0" ixz="0.0" iyz="0.0001" />
        </inertial>
    </link>
    <joint name="fixed" type="fixed">
        <parent link="world" />
        <child link="base_footprint" />
    </joint>
    <link name="base_link">
        <visual>
            <origin rpy="0 0 0" xyz="0 0 0" />
            <geometry>
                <mesh filename="package://ar3_model/meshes/base_link.STL" />
            </geometry>
            <material name="Orange">
                    <color rgba="1 0.5490 0.0 1.0"/>
            </material>
        </visual>
        <collision>
            <origin rpy="0 0 0" xyz="0 0 0" />
            <geometry>
                <mesh filename="package://ar3_model/meshes/base_link.STL" />
            </geometry>
        </collision>
        <inertial>
            <origin rpy="0 0 0" xyz="0 0 0" />
            <mass value="20" />
            <inertia ixx="1E-2" ixy="0" ixz="0" iyy="1E-2" iyz="0" izz="1E-2" />
        </inertial>
    </link>
    <joint name="base_link2base_footprint" type="fixed">
        <parent link="base_footprint" />
        <child link="base_link" />
        <origin xyz="0 0 0" />
    </joint>
    <link name="link_1">
        <visual>
            <origin rpy="0 0 0" xyz="0 0 0" />
            <geometry>
                <mesh filename="package://ar3_model/meshes/link_1.STL" />
            </geometry>
            <material name="">
                <color rgba="1 1 0 1" />
            </material>
        </visual>
        <collision>
            <origin rpy="0 0 0" xyz="0 0 0" />
            <geometry>
                <mesh filename="package://ar3_model/meshes/link_1.STL" />
            </geometry>
        </collision>
        <inertial>
            <origin rpy="0 0 0" xyz="0 0 0" />
            <mass value="0.01" />
            <inertia ixx="1E-2" ixy="0" ixz="0" iyy="1E-2" iyz="0" izz="1E-2" />
        </inertial>
    </link>
    <joint name="joint_1" type="revolute">
        <origin rpy="3.1415926 0 0" xyz="0 0 0.003445" />
        <parent link="base_link" />
        <child link="link_1" />
        <axis xyz="0 0 1" />
        <limit effort="1E8" lower="-2.96706" upper="2.96706" velocity="0.5" />
    </joint>
    <link name="link_2">
        <visual>
            <origin rpy="0 0 0" xyz="0 0 0" />
            <geometry>
                <mesh filename="package://ar3_model/meshes/link_2.STL" />
            </geometry>
            <material name="">
                <color rgba="1 1 0 1" />
            </material>
        </visual>
        <collision>
            <origin rpy="0 0 0" xyz="0 0 0" />
            <geometry>
                <mesh filename="package://ar3_model/meshes/link_2.STL" />
            </geometry>
        </collision>
        <inertial>
            <origin rpy="0 0 0" xyz="0 0 0" />
            <mass value="0.01" />
            <inertia ixx="1E-3" ixy="0" ixz="0" iyy="1E-3" iyz="0" izz="1E-3" />
        </inertial>
    </link>
    <joint name="joint_2" type="revolute">
        <origin rpy="1.5708 0.5236 -1.5708" xyz="0 0.064146 -0.16608" />
        <parent link="link_1" />
        <child link="link_2" />
        <axis xyz="0 0 -1" />
        <limit effort="1E15" lower="-0.6911503720000001" upper="1.5707963" velocity="0.5" />
    </joint>
    <link name="link_3">
        <visual>
            <origin rpy="0 0 0" xyz="0 0 0" />
            <geometry>
                <mesh filename="package://ar3_model/meshes/link_3.STL" />
            </geometry>
            <material name="">
                <color rgba="1 1 0 1" />
            </material>
        </visual>
        <collision>
            <origin rpy="0 0 0" xyz="0 0 0" />
            <geometry>
                <mesh filename="package://ar3_model/meshes/link_3.STL" />
            </geometry>
        </collision>
        <inertial>
            <origin rpy="0 0 0" xyz="0 0 0" />
            <mass value="0.01" />
            <inertia ixx="1E-3" ixy="0" ixz="0" iyy="1E-3" iyz="0" izz="1E-3" />
        </inertial>
    </link>
    <joint name="joint_3" type="revolute">
        <origin rpy="0 0 -1.04720367321" xyz="0.1525 -0.26414 0" />
        <parent link="link_2" />
        <child link="link_3" />
        <axis xyz="0 0 -1" />
        <limit effort="1E8" lower="0.0174533" upper="2.5080381" velocity="0.5" />
    </joint>
    <link name="link_4">
        <visual>
            <origin rpy="0 0 0" xyz="0 0 0" />
            <geometry>
                <mesh filename="package://ar3_model/meshes/link_4.STL" />
            </geometry>
            <material name="">
                <color rgba="1 1 0 1" />
            </material>
        </visual>
        <collision>
            <origin rpy="0 0 0" xyz="0 0 0" />
            <geometry>
                <mesh filename="package://ar3_model/meshes/link_4.STL" />
            </geometry>
        </collision>
        <inertial>
            <origin rpy="0 0 0" xyz="0 0 0" />
            <mass value="0.01" />
            <inertia ixx="1E-3" ixy="0" ixz="0" iyy="1E-3" iyz="0" izz="1E-3" />
        </inertial>
    </link>
    <joint name="joint_4" type="revolute">
        <origin rpy="1.5708 -1.2554 -1.5708" xyz="0 0 0.00675" />
        <parent link="link_3" />
        <child link="link_4" />
        <axis xyz="0 0 -1" />
        <limit effort="1E8" lower="-2.8710666" upper="2.8710666" velocity="0.5" />
    </joint>
    <link name="link_5">
        <visual>
            <origin rpy="0 0 0" xyz="0 0 0" />
            <geometry>
                <mesh filename="package://ar3_model/meshes/link_5.STL" />
            </geometry>
            <material name="">
                <color rgba="1 1 0 1" />
            </material>
        </visual>
        <collision>
            <origin rpy="0 0 0" xyz="0 0 0" />
            <geometry>
                <mesh filename="package://ar3_model/meshes/link_5.STL" />
            </geometry>
        </collision>
        <inertial>
            <origin rpy="0 0 0" xyz="0 0 0" />
            <mass value="0.01" />
            <inertia ixx="1E-3" ixy="0" ixz="0" iyy="1E-3" iyz="0" izz="1E-3" />
        </inertial>
    </link>
    <joint name="joint_5" type="revolute">
        <origin rpy="3.1415926 0 -2.8262" xyz="0 0 -0.22225" />
        <parent link="link_4" />
        <child link="link_5" />
        <axis xyz="1 0 0" />
        <limit effort="1E8" lower="-1.81776042" upper="1.81776042" velocity="0.5" />
    </joint>
    <link name="link_6">
        <visual>
            <origin rpy="0 0 0" xyz="0 0 0" />
            <geometry>
                <mesh filename="package://ar3_model/meshes/link_6.STL" />
            </geometry>
            <material name="">
                <color rgba="1 1 0 1" />
            </material>
        </visual>
        <collision>
            <origin rpy="0 0 0" xyz="0 0 0" />
            <geometry>
                <mesh filename="package://ar3_model/meshes/link_6.STL" />
            </geometry>
        </collision>
        <inertial>
            <origin rpy="0 0 0" xyz="0 0 0" />
            <mass value="0.01" />
            <inertia ixx="1E-3" ixy="0" ixz="0" iyy="1E-3" iyz="0" izz="1E-3" />
        </inertial>
    </link>
    <joint name="joint_6" type="revolute">
        <origin rpy="0 0 3.1416" xyz="-0.000294 0 0.02117" />
        <parent link="link_5" />
        <child link="link_6" />
        <axis xyz="0 0 1" />
        <limit effort="1E8" lower="-2.5848326" upper="2.5848326" velocity="0.5" />
    </joint>


    <link name="camera_link">
        <visual>
            <origin rpy="0 0 1.5707963" xyz="0 0 0" />
            <geometry>
                <box size="0.01 0.005 0.01" />
            </geometry>
        </visual>
        <collision>
            <origin rpy="0 0 1.5707963" xyz="0 0 0" />
            <geometry>
                <box size="0.01 0.005 0.01" />
            </geometry>
        </collision>
        <inertial>
            <origin rpy="0 0 1.5707963" xyz="0 0 0" />
            <mass value="0.001" />
            <inertia ixx="1.04167E-7" ixy="0" ixz="0" iyy="1.66667E-7" iyz="0" izz="1.04167E-7" />
        </inertial>
    </link>
    <joint name="camera_joint" type="fixed">
        <origin rpy="1.5707963 -1.5707963 0" xyz="0 0 0.016" />
        <!-- <origin rpy="0 0 0" xyz="0.044 0.023 0.1" /> -->
        <parent link="link_6" />
        <child link="camera_link" />
        <axis xyz="0 0 0" />
    </joint>



    <transmission name="trans_joint_1">
        <type>transmission_interface/SimpleTransmission</type>
        <joint name="joint_1">
            <hardwareInterface>hardware_interface/EffortJointInterface</hardwareInterface>
        </joint>
        <actuator name="joint_1_motor">
            <hardwareInterface>hardware_interface/EffortJointInterface</hardwareInterface>
            <mechanicalReduction>1</mechanicalReduction>
        </actuator>
    </transmission>
    <transmission name="trans_joint_2">
        <type>transmission_interface/SimpleTransmission</type>
        <joint name="joint_2">
            <hardwareInterface>hardware_interface/EffortJointInterface</hardwareInterface>
        </joint>
        <actuator name="joint_2_motor">
            <hardwareInterface>hardware_interface/EffortJointInterface</hardwareInterface>
            <mechanicalReduction>1</mechanicalReduction>
        </actuator>
    </transmission>
    <transmission name="trans_joint_3">
        <type>transmission_interface/SimpleTransmission</type>
        <joint name="joint_3">
            <hardwareInterface>hardware_interface/EffortJointInterface</hardwareInterface>
        </joint>
        <actuator name="joint_3_motor">
            <hardwareInterface>hardware_interface/EffortJointInterface</hardwareInterface>
            <mechanicalReduction>1</mechanicalReduction>
        </actuator>
    </transmission>
    <transmission name="trans_joint_4">
        <type>transmission_interface/SimpleTransmission</type>
        <joint name="joint_4">
            <hardwareInterface>hardware_interface/EffortJointInterface</hardwareInterface>
        </joint>
        <actuator name="joint_4_motor">
            <hardwareInterface>hardware_interface/EffortJointInterface</hardwareInterface>
            <mechanicalReduction>1</mechanicalReduction>
        </actuator>
    </transmission>
    <transmission name="trans_joint_5">
        <type>transmission_interface/SimpleTransmission</type>
        <joint name="joint_5">
            <hardwareInterface>hardware_interface/EffortJointInterface</hardwareInterface>
        </joint>
        <actuator name="joint_5_motor">
            <hardwareInterface>hardware_interface/EffortJointInterface</hardwareInterface>
            <mechanicalReduction>1</mechanicalReduction>
        </actuator>
    </transmission>
    <transmission name="trans_joint_6">
        <type>transmission_interface/SimpleTransmission</type>
        <joint name="joint_6">
            <hardwareInterface>hardware_interface/EffortJointInterface</hardwareInterface>
        </joint>
        <actuator name="joint_6_motor">
            <hardwareInterface>hardware_interface/EffortJointInterface</hardwareInterface>
            <mechanicalReduction>1</mechanicalReduction>
        </actuator>
    </transmission>
    <gazebo>
        <plugin name="gazebo_ros_control" filename="libgazebo_ros_control.so">
            <robotNamespace>/</robotNamespace>
        </plugin>
    </gazebo>


    <!-- camera -->
    <gazebo reference="camera_link">
        <sensor type="camera" name="RGBcamera">
            <update_rate>30</update_rate>
            <camera name="gripper_camera">
                <horizontal_fov>1.5707963</horizontal_fov>
                <image>
                    <width>1280</width>
                    <height>720</height>
                    <format>R8G8B8</format>
                </image>
                <clip>
                    <near>0.02</near>
                    <far>300</far>
                </clip>
                <noise>
                    <type>gaussian</type>
                    <mean>0.0</mean>
                    <stddev>0.007</stddev>
                </noise>
            </camera>
            <plugin name="camera_controller" filename="libgazebo_ros_camera.so">
                <alwaysOn>true</alwaysOn>
                <updateRate>0.0</updateRate>
                <cameraName>/gripper_camera</cameraName>
                <imageTopicName>image_raw</imageTopicName>    
                <cameraInfoTopicName>camera_info</cameraInfoTopicName>
                <frameName>camera_link</frameName>
                <hackBaseline>0.07</hackBaseline>
                <distortionK1>0.0</distortionK1>
                <distortionK2>0.0</distortionK2>
                <distortionK3>0.0</distortionK3>
                <distortionT1>0.0</distortionT1>
                <distortionT2>0.0</distortionT2>
            </plugin>
        </sensor>
        <sensor type="ray" name="gripper_laser">
            <pose>0 0 0 0 0 0</pose>
            <visualize>true</visualize>
            <update_rate>30</update_rate>
            <ray>
                <scan>
                    <horizontal>
                        <samples>20</samples>
                        <resolution>1</resolution>
                        <min_angle>-0.08726646</min_angle>
                        <max_angle>0.08726646</max_angle>
                    </horizontal>
                </scan>
                <range>
                    <min>0.01</min>
                    <max>1.0</max>
                    <resolution>0.01</resolution>
                </range>
                <noise>
                    <type>gaussian</type>
                    <mean>0.0</mean>
                    <stddev>0.01</stddev>
                </noise>
            </ray>
            <plugin name="gripper_laser_controller" filename="libgazebo_ros_laser.so">
                <topicName>/gripper/laser/scan</topicName>
                <frameName>camera_link</frameName>
            </plugin>
        </sensor>
    </gazebo>



    <gazebo reference="base_link">
        <material>Gazebo/Orange</material>
        <turnGravityOff>false</turnGravityOff>
    </gazebo>
    <gazebo reference="link_1">
        <material>Gazebo/Green</material>
        <turnGravityOff>false</turnGravityOff>
    </gazebo>
    <gazebo reference="link_2">
        <material>Gazebo/Grey</material>
        <turnGravityOff>false</turnGravityOff>
    </gazebo>
    <gazebo reference="link_3">
        <material>Gazebo/Green</material>
        <turnGravityOff>false</turnGravityOff>
    </gazebo>
    <gazebo reference="link_4">
        <material>Gazebo/Grey</material>
        <turnGravityOff>false</turnGravityOff>
    </gazebo>
    <gazebo reference="link_5">
        <material>Gazebo/Green</material>
        <turnGravityOff>false</turnGravityOff>
    </gazebo>
    <gazebo reference="link_6">
        <material>Gazebo/Grey</material>
        <turnGravityOff>false</turnGravityOff>
    </gazebo>
    <gazebo reference="link_7">
        <material>Gazebo/Grey</material>
        <turnGravityOff>false</turnGravityOff>
    </gazebo>
    <gazebo reference="camera_link">
        <material>Gazebo/Red</material>
        <turnGravityOff>false</turnGravityOff>
    </gazebo>


</robot>

